<mujoco model="gripper">

  <actuator>
    <motor name="gripper_motor_left_left" ctrllimited="true" ctrlrange="-1 1" gear="100" joint="left_gripper_link_joint_left"/>
    
  </actuator>

  <equality>
    <!-- Right Arm -->
    <joint joint1="left_gripper_link_joint_left" joint2="right_gripper_link_joint_left" polycoef="0 -1 0"/>
    <weld body1="rh_p12_rn_base_left" body2="right_gripper_tip_left" solref="0.02 1" solimp="0.95 0.95 0.001 0.5 6"/>
    <weld body1="rh_p12_rn_base_left" body2="left_gripper_tip_left" solref="0.02 1" solimp="0.95 0.95 0.001 0.5 6"/>
  </equality>


  <asset>
    <mesh name="z1_Link06" file="z1_Link06.STL"/>
    <mesh name="base" file="base.stl" scale="0.001 0.001 0.001"/>
    <mesh name="r1" file="r1.stl" scale="0.001 0.001 0.001"/>
    <mesh name="l1" file="l1.stl" scale="0.001 0.001 0.001"/>
    <mesh name="left_gripper_tip" file="left_gripper_tip.STL"/>
    <mesh name="right_gripper_tip" file="right_gripper_tip.STL"/>
    <mesh name="hand_adaptor" file="hand_adaptor.STL"/>
  </asset>

  <worldbody>
    <light pos="0 0 1.5" dir="0 0 -1" directional="true"/>
                    
    <body name="hand_adaptor_left" pos="0.0435 0 0" quat="0 -0.707107 0.707107 0">
      <inertial pos="7.82343e-06 0.00397537 0.00899299" quat="-0.00557049 0.707077 -0.00584137 0.707091" mass="0.0197175" diaginertia="1.28177e-05 7.5726e-06 5.97787e-06"/>
      <geom type="mesh" contype="0" conaffinity="0" group="1" density="0" mesh="hand_adaptor"/>
      
      <body name="rh_p12_rn_base_left" pos="0 -0.0103 0" quat="0.5 0.5 0.5 -0.5">
        <inertial pos="0 0 0.032" mass="0.236" diaginertia="1 1 1"/>
        <geom type="mesh" contype="0" conaffinity="0" group="1" density="0" rgba="0.2 0.2 0.2 1" mesh="base"/>
        <geom type="mesh" rgba="0.2 0.2 0.2 1" mesh="base"/>
        
        <body name="right_gripper_link_left" pos="0 0.008 0.048">
          <inertial pos="0 0.034 0.004" mass="0.068" diaginertia="1 1 1"/>                    
          <joint name="right_gripper_link_joint_left" pos="0 0 0" axis="1 0 0" range="0 1.12" actuatorfrcrange="-75 75" damping="1"/>
          <geom type="mesh" contype="0" conaffinity="0" group="1" density="0" rgba="0.2 0.2 0.2 1" mesh="r1"/>
          <geom type="mesh" rgba="0.2 0.2 0.2 1" mesh="r1"/>
          
          <body name="right_gripper_tip_left" pos="0 0.0493634 0.0285" quat="0.707105 0 0.707108 0">
            <inertial pos="-0.049583 0.011382 -1.4742e-07" quat="0.477699 0.477692 0.521352 0.52135" mass="0.067644" diaginertia="5.79491e-05 5.3981e-05 1.28539e-05"/>
            <joint name="right_gripper_tip_joint_left" pos="0 0 0" axis="0 0 1" range="-1.12 0" actuatorfrcrange="-5 5" damping="0.2"/>
            <geom type="mesh" contype="0" conaffinity="0" group="1" density="0" rgba="1 0.2 0.2 1" mesh="right_gripper_tip"/>
            <geom type="mesh" rgba="1 0.2 0.2 1" mesh="right_gripper_tip" friction="1 0.005 0.0001"/>
          </body>
        </body>
        
        <body name="left_gripper_link_left" pos="0 -0.008 0.048">
          <inertial pos="0 -0.034 0.004" mass="0.068" diaginertia="1 1 1"/>
          <joint name="left_gripper_link_joint_left" pos="0 0 0" axis="1 0 0" range="-1.12 0" actuatorfrcrange="-75 75" damping="1"/>
          <geom type="mesh" contype="0" conaffinity="0" group="1" density="0" rgba="0.2 0.2 0.2 1" mesh="l1"/>
          <geom type="mesh" rgba="0.2 0.2 0.2 1" mesh="l1"/>
          <body name="left_gripper_tip_left" pos="0 -0.0493634 0.0285" quat="9.38184e-07 0.707108 9.38187e-07 -0.707105">
            <inertial pos="-0.049583 0.011382 -1.4742e-07" quat="0.477699 0.477692 0.521352 0.52135" mass="0.067644" diaginertia="5.79491e-05 5.3981e-05 1.28539e-05"/>
            <joint name="left_gripper_tip_joint_left" pos="0 0 0" axis="0 0 1" range="-1.12 0" actuatorfrcrange="-5 5" damping="0.2"/>
            <geom type="mesh" contype="0" conaffinity="0" group="1" density="0" rgba="1 0.2 0.2 1" mesh="left_gripper_tip"/>
            <geom type="mesh" rgba="1 0.2 0.2 1" mesh="left_gripper_tip" friction="1 0.005 0.0001"/>
          </body>
        </body>
      </body>
    </body>
  </worldbody>
</mujoco>
