<mujoco model="zr">
  <compiler angle="radian"/>
  <include file="objects/coke/assets.xml"/>
  <option noslip_iterations="500" noslip_tolerance="1e-6" />

  <option>
        <flag multiccd="enable"/>
  </option>


  <actuator>
    <!-- Left Arm -->
    <motor name="link01_left" ctrllimited="true" ctrlrange="-0.5 0.5" gear="50" joint="joint_left_arm_1"/>
    <motor name="link02_left" ctrllimited="true" ctrlrange="-0.5 0.5" gear="50" joint="joint_left_arm_2"/>
    <motor name="link03_left" ctrllimited="true" ctrlrange="-0.5 0.5" gear="50" joint="joint_left_arm_3"/>
    <motor name="link04_left" ctrllimited="true" ctrlrange="-0.5 0.5" gear="50" joint="joint_left_arm_4"/>
    <motor name="link05_left" ctrllimited="true" ctrlrange="-0.5 0.5" gear="50" joint="joint_left_arm_5"/>
    <motor name="link06_left" ctrllimited="true" ctrlrange="-0.5 0.5" gear="50" joint="joint_left_arm_6"/>

    <motor name="gripper_motor_left_left" ctrllimited="true" ctrlrange="-1 1" gear="100" joint="left_gripper_link_joint_left"/>
    <!-- <motor joint="left_gripper_tip_joint_left" gear="100"/> -->
    <!-- <motor name="gripper_motor_right_left" ctrllimited="true" ctrlrange="-1 1" gear="-100" joint="right_gripper_link_joint_left"/> -->
    <!-- <motor joint="right_gripper_tip_joint_left" gear="-100"/> -->


    <!-- Right Arm -->
    <motor name="link01_right" ctrllimited="true" ctrlrange="-0.5 0.5" gear="50" joint="joint_right_arm_1"/>
    <motor name="link02_right" ctrllimited="true" ctrlrange="-0.5 0.5" gear="50" joint="joint_right_arm_2"/>
    <motor name="link03_right" ctrllimited="true" ctrlrange="-0.5 0.5" gear="50" joint="joint_right_arm_3"/>
    <motor name="link04_right" ctrllimited="true" ctrlrange="-0.5 0.5" gear="50" joint="joint_right_arm_4"/>
    <motor name="link05_right" ctrllimited="true" ctrlrange="-0.5 0.5" gear="50" joint="joint_right_arm_5"/>
    <motor name="link06_right" ctrllimited="true" ctrlrange="-0.5 0.5" gear="50" joint="joint_right_arm_6"/>

    <motor name="gripper_motor_left_right" ctrllimited="true" ctrlrange="-1 1" gear="100" joint="left_gripper_link_joint_right"/>
    <!-- <motor joint="left_gripper_tip_joint_right" gear="100"/> -->
    <!-- <motor name="gripper_motor_right_right" ctrllimited="true" ctrlrange="-1 1" gear="-100" joint="right_gripper_link_joint_right"/> -->
    <!-- <motor joint="right_gripper_tip_joint_right" gear="-100"/> -->

    
  </actuator>

  <contact>
    <exclude body1="right_gripper_link_left" body2="left_gripper_link_left"/>
    <exclude body1="right_gripper_tip_left" body2="left_gripper_tip_left"/>

    <exclude body1="right_gripper_link_right" body2="left_gripper_link_right"/>
    <exclude body1="right_gripper_tip_right" body2="left_gripper_tip_right"/>
  </contact>

  <equality>
    <!-- Left Arm -->
    <joint joint1="left_gripper_link_joint_left" joint2="right_gripper_link_joint_left" polycoef="0 -1 0"/>
    <weld body1="rh_p12_rn_base_left" body2="right_gripper_tip_left" solref="0.02 1" solimp="0.95 0.95 0.001 0.5 6"/>
    <weld body1="rh_p12_rn_base_left" body2="left_gripper_tip_left" solref="0.02 1" solimp="0.95 0.95 0.001 0.5 6"/>

    <!-- Right Arm -->
    <joint joint1="left_gripper_link_joint_right" joint2="right_gripper_link_joint_right" polycoef="0 -1 0"/>
    <!-- <weld body1="rh_p12_rn_base_right" body2="right_gripper_tip_right"/> -->
    <!-- <weld body1="rh_p12_rn_base_right" body2="left_gripper_tip_right"/> -->
    <weld body1="rh_p12_rn_base_right" body2="right_gripper_tip_right" solref="0.02 1" solimp="0.95 0.95 0.001 0.5 6"/>
    <weld body1="rh_p12_rn_base_right" body2="left_gripper_tip_right" solref="0.02 1" solimp="0.95 0.95 0.001 0.5 6"/>

  </equality>


  <asset>
    <mesh name="z1_Link00" file="z1_Link00.STL"/>
    <mesh name="z1_Link01" file="z1_Link01.STL"/>
    <mesh name="z1_Link02" file="z1_Link02.STL"/>
    <mesh name="z1_Link03" file="z1_Link03.STL"/>
    <mesh name="z1_Link04" file="z1_Link04.STL"/>
    <mesh name="z1_Link05" file="z1_Link05.STL"/>
    <mesh name="z1_Link06" file="z1_Link06.STL"/>
    <mesh name="hand_adaptor" file="hand_adaptor.STL"/>
    <mesh name="base" file="base.stl" scale="0.001 0.001 0.001"/>
    <mesh name="r1" file="r1.stl" scale="0.001 0.001 0.001"/>
    <mesh name="l1" file="l1.stl" scale="0.001 0.001 0.001"/>
    <mesh name="left_gripper_tip" file="left_gripper_tip.STL"/>
    <mesh name="right_gripper_tip" file="right_gripper_tip.STL"/>


    <!-- <texture name="checkerboard" type="2d" builtin="checker" width="512" height="512" rgb1="0 0 0.5" rgb2="0.6 0.8 1" mark="none" /> -->
    <!-- <material name="checker_mat" texture="groundplane" texrepeat="2 2" /> -->
    <texture type="2d" name="groundplane" builtin="checker" mark="edge" rgb1="0.2 0.3 0.4" rgb2="0.1 0.2 0.3"
      markrgb="0.8 0.8 0.8" width="300" height="300"/>
    <material name="groundplane" texture="groundplane" texuniform="true" texrepeat="5 5" reflectance="0.2"/>
  
    <mesh file="objects/can.obj" scale="0.007 0.007 0.007" />
    <mesh file="objects/Corona.obj" scale="0.005 0.005 0.005" />
  </asset>

  <worldbody>
    <light pos="0 0 1.5" dir="0 0 -1" directional="true"/>
    <geom name="floor" size="0 0 0.05" type="plane" material="groundplane"/>
    
    

    <body name="link00_left" pos="0 0.215 0.06">
      <inertial pos="-0.00334984 -0.00013615 0.0249584" quat="-0.00692194 0.682592 0.00133293 0.730766" mass="0.472475" diaginertia="0.000531375 0.000415207 0.000378658"/>
      <geom type="mesh" contype="0" conaffinity="0" group="1" density="0" mesh="z1_Link00"/>
      <body name="link01_left" pos="0 0 0.0585">
        <inertial pos="2.47e-06 -0.00025198 0.0231717" quat="0.708578 0.705633 0.000281462 -0.000355927" mass="0.673326" diaginertia="0.00128328 0.000839362 0.000719308"/>
        <joint name="joint_left_arm_1" pos="0 0 0" axis="0 0 1" range="-2.61799 2.61799" actuatorfrcrange="-30 30" damping="15" frictionloss="1"/>
        <geom type="mesh" contype="0" conaffinity="0" group="1" density="0" mesh="z1_Link01"/>
        <body name="link02_left" pos="0 0 0.045">
          <inertial pos="-0.110126 0.00240029 0.00158266" quat="0.00748058 0.707092 -0.0114473 0.70699" mass="1.19132" diaginertia="0.0246612 0.0243113 0.00100468"/>
          <joint name="joint_left_arm_2" pos="0 0 0" axis="0 1 0" range="0 2.96706" actuatorfrcrange="-60 60" damping="15" frictionloss="2"/>
          <geom type="mesh" contype="1" conaffinity="1" group="1" density="0" mesh="z1_Link02"/>
          <body name="link03_left" pos="-0.35 0 0">
            <inertial pos="0.106092 -0.00541815 0.0347638" quat="0.540557 0.443575 0.426319 0.573839" mass="0.839409" diaginertia="0.00954365 0.00938711 0.000558432"/>
            <joint name="joint_left_arm_3" pos="0 0 0" axis="0 1 0" range="-2.87979 0" actuatorfrcrange="-30 30" damping="15" frictionloss="1"/>
            <geom type="mesh" contype="1" conaffinity="1" group="1" density="0" mesh="z1_Link03"/>
            <body name="link04_left" pos="0.218 0 0.057">
              <inertial pos="0.0436668 0.00364738 -0.00170192" quat="0.0390835 0.726445 -0.0526787 0.684087" mass="0.564046" diaginertia="0.000981656 0.00094053 0.000302655"/>
              <!-- <joint name="joint_arm_4" pos="0 0 0" axis="0 -1 0" range="-1.51844 1.51844" actuatorfrcrange="-30 30" damping="15" frictionloss="1"/> -->
              <joint name="joint_left_arm_4" pos="0 0 0" axis="0 1 0" range="-1.51844 1.51844" actuatorfrcrange="-30 30" damping="15" frictionloss="1"/>
              <geom type="mesh" contype="1" conaffinity="1" group="1" density="0" mesh="z1_Link04"/>
              <body name="link05_left" pos="0.07 0 0">
                <inertial pos="0.0312153 0 0.00646316" quat="0.462205 0.535209 0.53785 0.45895" mass="0.389385" diaginertia="0.000558961 0.000547317 0.000167332"/>
                <joint name="joint_left_arm_5" pos="0 0 0" axis="0 0 1" range="-1.3439 1.3439" actuatorfrcrange="-30 30" damping="15" frictionloss="1"/>
                <geom type="mesh" contype="0" conaffinity="0" group="1" density="0" mesh="z1_Link05"/>
                <body name="link06_left" pos="0.0492 0 0">
                  <inertial pos="0.0241569 -0.00017355 -0.00143876" quat="0.998779 0.0457735 -0.00663717 0.0173548" mass="0.288758" diaginertia="0.00018333 0.000147464 0.000146786"/>
                  <joint name="joint_left_arm_6" pos="0 0 0" axis="1 0 0" range="-2.79253 2.79253" actuatorfrcrange="-30 30" damping="15" frictionloss="1"/>
                  <geom type="mesh" contype="0" conaffinity="0" group="1" density="0" mesh="z1_Link06"/>
                  <body name="hand_adaptor_left" pos="0.0435 0 0" quat="0 -0.707107 0.707107 0">
                    <inertial pos="7.82343e-06 0.00397537 0.00899299" quat="-0.00557049 0.707077 -0.00584137 0.707091" mass="0.0197175" diaginertia="1.28177e-05 7.5726e-06 5.97787e-06"/>
                    <geom type="mesh" contype="0" conaffinity="0" group="1" density="0" mesh="hand_adaptor"/>
                    
                    <body name="rh_p12_rn_base_left" pos="0 -0.0103 0" quat="0.5 0.5 0.5 -0.5">
                      <inertial pos="0 0 0.032" mass="0.236" diaginertia="1 1 1"/>
                      <geom type="mesh" contype="0" conaffinity="0" group="1" density="0" rgba="0.2 0.2 0.2 1" mesh="base"/>
                      <geom type="mesh" rgba="0.2 0.2 0.2 1" mesh="base"/>
                      
                      <body name="right_gripper_link_left" pos="0 0.008 0.048">
                        <inertial pos="0 0.034 0.004" mass="0.068" diaginertia="1 1 1"/>                    
                        <joint name="right_gripper_link_joint_left" pos="0 0 0" axis="1 0 0" range="0 1.12" actuatorfrcrange="-1500 1500" damping="3"/>
                        <geom type="mesh" contype="0" conaffinity="0" group="1" density="0" rgba="0.2 0.2 0.2 1" mesh="r1"/>
                        <geom type="mesh" rgba="0.2 0.2 0.2 1" mesh="r1"/>
                        
                        <body name="right_gripper_tip_left" pos="0 0.0493634 0.0285" quat="0.707105 0 0.707108 0">
                          <inertial pos="-0.69583 0.21382 -1.4742e-06" quat="0.477699 0.477692 0.521352 0.52135" mass="0.067644"  diaginertia="5.79491e-05 5.3981e-05 1.28539e-05"/>
                          <!-- <inertial pos="-0.049583 0.011382 -1.4742e-07" quat="0.477699 0.477692 0.521352 0.52135" mass="0.067644" diaginertia="5.79491e-05 5.3981e-05 1.28539e-05"/> -->
                          <joint name="right_gripper_tip_joint_left" pos="0 0 0" axis="0 0 1" range="-1.12 0" actuatorfrcrange="-1000 1000" damping="0.2"/>
                          <geom type="mesh" contype="0" conaffinity="0" group="1" density="0" rgba="1 0.2 0.2 1" mesh="right_gripper_tip"/>
                          <geom type="box" size="0.054 0.01 0.02" pos="-0.064 0.008 0" rgba="1 1 1 0" friction="0.1"/>
                          <!-- <geom type="mesh" rgba="1 0.2 0.2 1" mesh="right_gripper_tip" friction="1 0.005 0.0001"/> -->
                        </body>
                      </body>
                      
                      <body name="left_gripper_link_left" pos="0 -0.008 0.048">
                        <inertial pos="0 -0.034 0.004" mass="0.068" diaginertia="1 1 1"/>
                        <joint name="left_gripper_link_joint_left" pos="0 0 0" axis="1 0 0" range="-1.12 0" actuatorfrcrange="-1500 1500" damping="3"/>
                        <geom type="mesh" contype="0" conaffinity="0" group="1" density="0" rgba="0.2 0.2 0.2 1" mesh="l1"/>
                        <geom type="mesh" rgba="0.2 0.2 0.2 1" mesh="l1"/>
                        <body name="left_gripper_tip_left" pos="0 -0.0493634 0.0285" quat="9.38184e-07 0.707108 9.38187e-07 -0.707105">
                          <inertial pos="-0.69583 0.21382 -1.4742e-06" quat="0.477699 0.477692 0.521352 0.52135" mass="0.067644"  diaginertia="5.79491e-05 5.3981e-05 1.28539e-05"/>
                          <!-- <inertial pos="-0.049583 0.011382 -1.4742e-07" quat="0.477699 0.477692 0.521352 0.52135" mass="0.067644" diaginertia="5.79491e-05 5.3981e-05 1.28539e-05"/> -->
                          <joint name="left_gripper_tip_joint_left" pos="0 0 0" axis="0 0 1" range="-1.12 0" actuatorfrcrange="-1000 1000" damping="0.2"/>
                          <geom type="mesh" contype="0" conaffinity="0" group="1" density="0" rgba="1 0.2 0.2 1" mesh="left_gripper_tip"/>
                          <geom type="box" size="0.054 0.01 0.02" pos="-0.064 0.008 0" rgba="1 1 1 0" friction="0.1"/>
                          <!-- <geom type="mesh" rgba="1 0.2 0.2 1" mesh="left_gripper_tip" friction="1 0.005 0.0001"/> -->
                        </body>
                      </body>
                    </body>
                  </body>
                </body>
              </body>
            </body>
          </body>
        </body>
      </body>
    </body>

    <body name="link00_right" pos="0 -0.215 0.06">
      <inertial pos="-0.00334984 -0.00013615 0.0249584" quat="-0.00692194 0.682592 0.00133293 0.730766" mass="0.472475" diaginertia="0.000531375 0.000415207 0.000378658"/>
      <geom type="mesh" contype="0" conaffinity="0" group="1" density="0" mesh="z1_Link00"/>
      <body name="link01_right" pos="0 0 0.0585">
        <inertial pos="2.47e-06 -0.00025198 0.0231717" quat="0.708578 0.705633 0.000281462 -0.000355927" mass="0.673326" diaginertia="0.00128328 0.000839362 0.000719308"/>
        <joint name="joint_right_arm_1" pos="0 0 0" axis="0 0 1" range="-2.61799 2.61799" actuatorfrcrange="-30 30" damping="15" frictionloss="1"/>
        <geom type="mesh" contype="0" conaffinity="0" group="1" density="0" mesh="z1_Link01"/>
        <body name="link02_right" pos="0 0 0.045">
          <inertial pos="-0.110126 0.00240029 0.00158266" quat="0.00748058 0.707092 -0.0114473 0.70699" mass="1.19132" diaginertia="0.0246612 0.0243113 0.00100468"/>
          <joint name="joint_right_arm_2" pos="0 0 0" axis="0 1 0" range="0 2.96706" actuatorfrcrange="-60 60" damping="15" frictionloss="2"/>
          
          <geom type="mesh" contype="1" conaffinity="1" group="1" density="0" mesh="z1_Link02"/>
          <body name="link03_right" pos="-0.35 0 0">
            <inertial pos="0.106092 -0.00541815 0.0347638" quat="0.540557 0.443575 0.426319 0.573839" mass="0.839409" diaginertia="0.00954365 0.00938711 0.000558432"/>
            <joint name="joint_right_arm_3" pos="0 0 0" axis="0 1 0" range="-2.87979 0" actuatorfrcrange="-30 30" damping="15" frictionloss="1"/>
            
            <geom type="mesh" contype="1" conaffinity="1" group="1" density="0" mesh="z1_Link03"/>
            <body name="link04_right" pos="0.218 0 0.057">
              <inertial pos="0.0436668 0.00364738 -0.00170192" quat="0.0390835 0.726445 -0.0526787 0.684087" mass="0.564046" diaginertia="0.000981656 0.00094053 0.000302655"/>
              <!-- <joint name="joint_arm_4" pos="0 0 0" axis="0 -1 0" range="-1.51844 1.51844" actuatorfrcrange="-30 30" damping="15" frictionloss="1"/> -->
              <joint name="joint_right_arm_4" pos="0 0 0" axis="0 1 0" range="-1.51844 1.51844" actuatorfrcrange="-30 30" damping="15" frictionloss="1"/>
              <geom type="mesh" contype="1" conaffinity="1" group="1" density="0" mesh="z1_Link04"/>
              
              <body name="link05_right" pos="0.07 0 0">
                <inertial pos="0.0312153 0 0.00646316" quat="0.462205 0.535209 0.53785 0.45895" mass="0.389385" diaginertia="0.000558961 0.000547317 0.000167332"/>
                <joint name="joint_right_arm_5" pos="0 0 0" axis="0 0 1" range="-1.3439 1.3439" actuatorfrcrange="-30 30" damping="15" frictionloss="1"/>
                <geom type="mesh" contype="0" conaffinity="0" group="1" density="0" mesh="z1_Link05"/>
                <body name="link06_right" pos="0.0492 0 0">
                  <inertial pos="0.0241569 -0.00017355 -0.00143876" quat="0.998779 0.0457735 -0.00663717 0.0173548" mass="0.288758" diaginertia="0.00018333 0.000147464 0.000146786"/>
                  <joint name="joint_right_arm_6" pos="0 0 0" axis="1 0 0" range="-2.79253 2.79253" actuatorfrcrange="-30 30" damping="15" frictionloss="1"/>
                  <geom type="mesh" contype="0" conaffinity="0" group="1" density="0" mesh="z1_Link06"/>
                  <body name="hand_adaptor_right" pos="0.0435 0 0" quat="0 -0.707107 0.707107 0">
                    <inertial pos="7.82343e-06 0.00397537 0.00899299" quat="-0.00557049 0.707077 -0.00584137 0.707091" mass="0.0197175" diaginertia="1.28177e-05 7.5726e-06 5.97787e-06"/>
                    <geom type="mesh" contype="0" conaffinity="0" group="1" density="0" mesh="hand_adaptor"/>
                    
                    <body name="rh_p12_rn_base_right" pos="0 -0.0103 0" quat="0.5 0.5 0.5 -0.5">
                      <inertial pos="0 0 0.032" mass="0.236" diaginertia="1 1 1"/>
                      <geom type="mesh" contype="0" conaffinity="0" group="1" density="0" rgba="0.2 0.2 0.2 1" mesh="base"/>
                      <geom type="mesh" rgba="0.2 0.2 0.2 1" mesh="base"/>
                      
                      <body name="right_gripper_link_right" pos="0 0.008 0.048">
                        <inertial pos="0 0.034 0.004" mass="0.068" diaginertia="1 1 1"/>                    
                        <joint name="right_gripper_link_joint_right" pos="0 0 0" axis="1 0 0" range="0 1.12" actuatorfrcrange="-1500 1500" damping="3"/>
                        <geom type="mesh" contype="0" conaffinity="0" group="1" density="0" rgba="0.2 0.2 0.2 1" mesh="r1"/>
                        <geom type="mesh" rgba="0.2 0.2 0.2 1" mesh="r1"/>
                        
                        <body name="right_gripper_tip_right" pos="0 0.0493634 0.0285" quat="0.707105 0 0.707108 0">
                          <inertial pos="-0.69583 0.21382 -1.4742e-06" quat="0.477699 0.477692 0.521352 0.52135" mass="0.067644"  diaginertia="5.79491e-05 5.3981e-05 1.28539e-05"/>
                          <!-- <inertial pos="-0.049583 0.011382 -1.4742e-07" quat="0.477699 0.477692 0.521352 0.52135" mass="0.067644" diaginertia="5.79491e-05 5.3981e-05 1.28539e-05"/> -->
                          <joint name="right_gripper_tip_joint_right" pos="0 0 0" axis="0 0 1" range="-1.12 0" actuatorfrcrange="-1000 1000" damping="0.2"/>
                          <geom type="mesh" contype="0"  conaffinity="0" group="1" density="0" rgba="1 0.2 0.2 1" mesh="right_gripper_tip"/>
                          <geom type="box" size="0.054 0.01 0.02" pos="-0.064 0.008 0" rgba="1 1 1 0" friction="0.1"/>
                          <!-- <geom type="mesh" rgba="1 0.2 0.2 1" mesh="right_gripper_tip"  friction="0.1 0.002 0.0001"/> -->
                        </body>
                      </body>
                      
                      <body name="left_gripper_link_right" pos="0 -0.008 0.048">
                        <inertial pos="0 -0.034 0.004" mass="0.068" diaginertia="1 1 1"/>
                        <joint name="left_gripper_link_joint_right" pos="0 0 0" axis="1 0 0" range="-1.12 0" actuatorfrcrange="-1500 1500" damping="3"/>
                        <geom type="mesh" contype="0" conaffinity="0" group="1" density="0" rgba="0.2 0.2 0.2 1" mesh="l1"/>
                        <geom type="mesh" rgba="0.2 0.2 0.2 1" mesh="l1"/>
                        
                        <body name="left_gripper_tip_right" pos="0 -0.0493634 0.0285" quat="9.38184e-07 0.707108 9.38187e-07 -0.707105">
                        <!-- <body name="left_gripper_tip_right" pos="0 -0.0493634 0.0285" quat="9.38184e-07 0.707108 9.38187e-07 -0.707105"> -->
                          <inertial pos="-0.69583 0.21382 -1.4742e-06" quat="0.477699 0.477692 0.521352 0.52135" mass="0.067644"  diaginertia="5.79491e-05 5.3981e-05 1.28539e-05"/>
                          <!-- <inertial pos="-0.049583 0.011382 -1.4742e-07" quat="0.477699 0.477692 0.521352 0.52135" mass="0.067644" diaginertia="5.79491e-05 5.3981e-05 1.28539e-05"/> -->
                          <joint name="left_gripper_tip_joint_right" pos="0 0 0" axis="0 0 1" range="-1.12 0" actuatorfrcrange="-1000 1000" damping="0.2"/>
                          <geom type="mesh" contype="0"  conaffinity="0" group="1" density="0" rgba="1 0.2 0.2 1" mesh="left_gripper_tip"/>
                          <geom type="box" size="0.054 0.01 0.02" pos="-0.064 0.008 0" rgba="1 1 1 0" friction="0.1"/>
                          <!-- <geom type="mesh" rgba="1 0.2 0.2 1" mesh="left_gripper_tip"  friction="0.1 0.002 0.0001"/> -->
                          
                        </body>
                      </body>
                    </body>
                  </body>
                </body>
              </body>
            </body>
          </body>
        </body>
      </body>
    </body>


    <!-- Objects -->
    <!-- <body name="can1" pos="0.17 -0.2  0.1" quat="0 0 0 1"> -->
    <body name="can1" pos="0.5 0.1 0.1" quat="0 0 0 1">
        <!-- <freejoint /> -->
        <joint name="can1_joint" type="free" frictionloss="0.01" />
        <inertial pos="0 0 0.05" mass="0.1" diaginertia="0.0005 0.0005 0.0005" />
        <geom type="mesh" mesh="can" material="lambert7SG" friction="0.01" />
        <!-- <geom type="cylinder" mesh="can" material="lambert7SG" friction="0.01" /> -->
    </body>
    <!-- <body name="can2" pos="0.5 0.1 0.1" quat="0 0 0 1"> -->
    <body name="can2" pos="0.17 -0.2  0.1" quat="0 0 0 1">
    <!-- <body name="can2" pos="0.5 -0.1 0.1" quat="0 0 0 1"> -->
        <freejoint />
        <!-- <inertial pos="0 0 0" mass="0.1" diaginertia="0.00001 0.000001 0.000001" /> -->
        <geom type="box" size="0.02 0.02 0.02" friction="0.2 0.01 0.01"/>
        <!-- <geom type="cylinder" size="0.01 0.05 1" friction="0.1 0.015 0.0005" /> -->
    </body>
    <body> 
      <camera name="agent_view" mode="fixed" pos="-0.12 0 0.6" quat="0.653 0.271 -0.271 -0.653"/>
    </body>
  </worldbody>

  <!-- Camera -->
</mujoco>
